Traceback (most recent call last):
  File "/usr/local/anaconda3/envs/jupyer-book/lib/python3.9/site-packages/jupyter_cache/executors/utils.py", line 51, in single_nb_execution
    executenb(
  File "/usr/local/anaconda3/envs/jupyer-book/lib/python3.9/site-packages/nbclient/client.py", line 1087, in execute
    return NotebookClient(nb=nb, resources=resources, km=km, **kwargs).execute()
  File "/usr/local/anaconda3/envs/jupyer-book/lib/python3.9/site-packages/nbclient/util.py", line 74, in wrapped
    return just_run(coro(*args, **kwargs))
  File "/usr/local/anaconda3/envs/jupyer-book/lib/python3.9/site-packages/nbclient/util.py", line 53, in just_run
    return loop.run_until_complete(coro)
  File "/usr/local/anaconda3/envs/jupyer-book/lib/python3.9/asyncio/base_events.py", line 642, in run_until_complete
    return future.result()
  File "/usr/local/anaconda3/envs/jupyer-book/lib/python3.9/site-packages/nbclient/client.py", line 540, in async_execute
    await self.async_execute_cell(
  File "/usr/local/anaconda3/envs/jupyer-book/lib/python3.9/site-packages/nbclient/client.py", line 832, in async_execute_cell
    self._check_raise_for_error(cell, exec_reply)
  File "/usr/local/anaconda3/envs/jupyer-book/lib/python3.9/site-packages/nbclient/client.py", line 740, in _check_raise_for_error
    raise CellExecutionError.from_cell_and_msg(cell, exec_reply['content'])
nbclient.exceptions.CellExecutionError: An error occurred while executing the following cell:
------------------
fig_6_3 <- ggplot(data = pop_data, # data frame not subset
                  aes(x = N_billions, 
                      y = `1/N deltaN/deltat`)) +
  geom_point(color='blue') + theme_classic() +
  scale_x_continuous(name = expression(paste(italic("N,"), " population in billions")),
                     breaks = seq(0, 12),
                     limits = c(0, 12)) +
  scale_y_continuous(name = expression(paste(frac(1, italic("N")), " ", frac(italic("dN"), italic("dt")))),
                     breaks = seq(0, .03, by = 0.01),
                     limits = c(0, 0.03)) +
  geom_abline(slope = 0.00648, intercept = -0.001185 ) +
  annotate("text", x = 1, y = 0.02, label = expression(italic("r") == -0.001185)) + 
  annotate("text", x = 0.9, y = 0.018, label = expression(italic("s") == 0.00648)) +
  geom_abline(slope = -0.00289, intercept = 0.03077, colour = "red" ) +             # the second down-slope best fit line
  annotate("text", x = 6, y = 0.01, label = expression(italic("r") == 0.03077)) + 
  annotate("text", x = 6, y = 0.007, label = expression(italic("s") == -0.00289))

fig_6_3
------------------

Error in ggplot(data = pop_data, aes(x = N_billions, y = `1/N deltaN/deltat`)): object 'pop_data' not found
Traceback:

1. ggplot(data = pop_data, aes(x = N_billions, y = `1/N deltaN/deltat`))
ERROR: Error in ggplot(data = pop_data, aes(x = N_billions, y = `1/N deltaN/deltat`)): object 'pop_data' not found


