Traceback (most recent call last):
  File "/usr/local/anaconda3/envs/jupyer-book/lib/python3.9/site-packages/jupyter_cache/executors/utils.py", line 51, in single_nb_execution
    executenb(
  File "/usr/local/anaconda3/envs/jupyer-book/lib/python3.9/site-packages/nbclient/client.py", line 1087, in execute
    return NotebookClient(nb=nb, resources=resources, km=km, **kwargs).execute()
  File "/usr/local/anaconda3/envs/jupyer-book/lib/python3.9/site-packages/nbclient/util.py", line 74, in wrapped
    return just_run(coro(*args, **kwargs))
  File "/usr/local/anaconda3/envs/jupyer-book/lib/python3.9/site-packages/nbclient/util.py", line 53, in just_run
    return loop.run_until_complete(coro)
  File "/usr/local/anaconda3/envs/jupyer-book/lib/python3.9/asyncio/base_events.py", line 642, in run_until_complete
    return future.result()
  File "/usr/local/anaconda3/envs/jupyer-book/lib/python3.9/site-packages/nbclient/client.py", line 540, in async_execute
    await self.async_execute_cell(
  File "/usr/local/anaconda3/envs/jupyer-book/lib/python3.9/site-packages/nbclient/client.py", line 832, in async_execute_cell
    self._check_raise_for_error(cell, exec_reply)
  File "/usr/local/anaconda3/envs/jupyer-book/lib/python3.9/site-packages/nbclient/client.py", line 740, in _check_raise_for_error
    raise CellExecutionError.from_cell_and_msg(cell, exec_reply['content'])
nbclient.exceptions.CellExecutionError: An error occurred while executing the following cell:
------------------
:tags: ["hide-input"]
suppressPackageStartupMessages({
  library(tidyverse)
}) # hide annoying messages
# data from https://ourworldindata.org/world-population-growth
worldPopulation <- read_csv("../data/WorldPopulationAnnual12000years_interpolated_HYDEandUNto2015.csv", skip = 1, col_names = c("year", "population"), col_types = "nn")
filter(worldPopulation, year > 0) %>% ggplot(aes(year, population/10^9)) + geom_line() + 
  annotate("segment", x = 476, y = 2, xend = 476, yend = .5, colour = "blue", arrow = arrow(type = "closed", length = unit(0.02, "npc"))) +
  annotate("text", x = 476, y = 2, label = "Fall of Rome", color = "blue", angle = 90, hjust = - .1, fontface = "bold") + 
  annotate("segment", x = 476, y = 2, xend = 476, yend = .5, color = "blue", arrow = arrow(type = "closed", length = unit(0.02, "npc"))) +
  annotate("rect", xmin = c(500,500), xmax = c(1500,1500), ymin = c(.1, .1), ymax = c(0.9, 0.9), alpha=0.1, color=NA, fill="blue") + 
  annotate("text", x = 1000, y = .6, label = "Middle Ages", color = "blue", fontface = "bold") + 
  annotate("segment", x = 1666, y = 2, xend = 1666, yend = .6, colour = "blue", arrow = arrow(type = "closed", length = unit(0.02, "npc"))) +
  annotate("text", x = 1666, y = 2, label = "Great Plague of London", color = "blue", angle = 90, hjust = - .1, fontface = "bold") + 
  annotate("segment", x = 1346, y = 2, xend = 1346, yend = .6, colour = "blue", arrow = arrow(type = "closed", length = unit(0.02, "npc"))) +
  annotate("text", x = 1346, y = 2, label = "Black Death", color = "blue", angle = 90, hjust = - .1, fontface = "bold") + 
  theme_bw() + xlab(expression(paste(italic(t), ", Year"))) + ylab(expression(paste(italic(N), ", World Population (billions)")))
------------------

Error in parse(text = x, srcfile = src): <text>:1:1: unexpected ':'
1: :
    ^
Traceback:

ERROR: Error in parse(text = x, srcfile = src): <text>:1:1: unexpected ':'
1: :
    ^


